Workbook

Sheet Premissas
A1: PLANILHA DE CUSTOS — PREGÃO ELETRÔNICO 036/2026 — PREFEITURA DE HOLAMBRA/SP — Transporte escolar (ônibus 59 lugares)
A2: Legenda: azul = dado de entrada (edite à vontade) · fundo amarelo = preencher · preto = fórmula · verde = link de outra aba. Todas as premissas de custo são ESTIMATIVAS DE MERCADO (SP, set/2026) — substitua pelos números reais da Azul Mob.
A4: Item | B4: Valor | C4: Unid. | D4: Observação / fonte
A5: 1. DADOS DO LICITANTE (Anexo II)
A6: Denominação | B6: AZUL TRANSPORTES E TURISMO LTDA | D6: Razão social conforme CNPJ (nome fantasia: Azul Mob).
A7: Endereço | D7: PREENCHER — endereço completo da sede (São Paulo/SP).
A8: CNPJ | B8: 10.764.533/0001-01
A9: Telefone | D9: PREENCHER
A10: E-mail | D10: PREENCHER
A11: Responsável pela assinatura do contrato (nome) | D11: PREENCHER
A12: RG | D12: PREENCHER
A13: CPF | D13: PREENCHER
A14: Cargo | D14: PREENCHER (ex.: Sócio-administrador)
A15: Cidade, dia, mês e ano da proposta | B15: São Paulo, 28 de setembro de 2026 | D15: Sessão do pregão: 28/09/2026 (título do arquivo enviado).
A17: 2. PARÂMETROS DO CONTRATO
A18: Dias letivos considerados no edital | B18: 200 | C18: dias | D18: Derivado do edital: em todas as 9 linhas, KM total ÷ KM por dia = 200 (ex.: Linha 01: 27.160 ÷ 135,8 = 200).
A19: Meses de custo fixo (salários, veículo) no período | B19: 12 | C19: meses | D19: 200 dias letivos ≈ ano letivo completo. A equipe e o veículo custam também nos meses sem aula (férias/recesso). Ajuste se o contrato for menor.
A20: Km morto / deslocamento garagem ↔ ponto inicial | B20: 0.1 | C20: % do km | D20: Estimativa: 10% sobre o km pago. Depende de onde ficará a garagem de apoio em Holambra.
A21: Reserva técnica de frota | B21: 0.1 | C21: % da frota | D21: 1 ônibus reserva a cada 10 (edital costuma exigir veículo reserva). Aplicado sobre o custo fixo do veículo.
A23: 3. PESSOAL (por funcionário)
A24: Salário base — motorista de ônibus (cat. D) | B24: 3200 | C24: R$/mês | D24: ESTIMATIVA. Conferir CCT vigente (SETPESP / Sindicato dos Motoristas) para transporte escolar/fretamento interior SP, 2026.
A25: Salário base — monitora escolar | B25: 1900 | C25: R$/mês | D25: ESTIMATIVA (piso ≈ salário mínimo 2026 + acréscimo). Conferir CCT.
A26: Encargos e provisões sobre salário | B26: 0.7 | C26: % | D26: INSS patronal + RAT + terceiros (~28,8%), FGTS 8%, provisão férias + 1/3, 13º, rescisão/multa FGTS — total típico 68–72% no regime CLT (não Simples).
A27: Fator jornada estendida — linhas com período NOTURNO | B27: 1.35 | C27: x | D27: Linhas 01, 04 e 06 rodam de 5h50 às 23h00: jornada excede 8h → horas extras (50%) + adicional noturno (20%) ou 2º motorista parcial. Fator sobre o custo do motorista.
A28: Benefícios — VR/VA + cesta + seguro de vida | B28: 780 | C28: R$/mês por func. | D28: ESTIMATIVA: VA R$ 26/dia × 22 + cesta R$ 200 + seguro/assist. R$ 8. Vale-transporte tende a zero (equipe local, rural).
A29: Uniforme / EPI / exames (ASO, toxicológico) | B29: 60 | C29: R$/mês por func. | D29: ESTIMATIVA rateada.
A31: 4. VEÍCULO — ônibus mín. 59 lugares (custo fixo mensal por veículo)
A32: Valor do ônibus (usado, ~8 anos, 59 lug., adequado escolar) | B32: 280000 | C32: R$ | D32: ESTIMATIVA de mercado set/2026. Se usar veículo já da frota Azul, informe o valor contábil/FIPE.
A33: Depreciação anual | B33: 0.12 | C33: % a.a. | D33: Linear, vida útil restante ~8 anos com residual.
A34: Custo de capital / financiamento | B34: 0.14 | C34: % a.a. | D34: Frota Azul é financiada via CDC/consórcio — use a taxa média real dos contratos.
A35: Seguro RC + casco (rateio mensal) | B35: 1100 | C35: R$/mês | D35: ESTIMATIVA. Apólice escolar Sombrero — conferir prêmio real/veículo.
A36: IPVA + licenciamento + DPVAT (anual) | B36: 4200 | C36: R$/ano | D36: IPVA SP ônibus 1,5% s/ valor venal + taxas.
A37: Rastreamento / telemetria (Ituran) | B37: 90 | C37: R$/mês | D37: Valor contratual Azul (estimado).
A38: Inspeção escolar semestral + vistoria + tacógrafo (anual) | B38: 900 | C38: R$/ano | D38: ESTIMATIVA.
A39: Garagem / ponto de apoio em Holambra (rateio por veículo) | B39: 450 | C39: R$/mês por veíc. | D39: ESTIMATIVA: aluguel de pátio ~R$ 4.500/mês ÷ 10 veículos. Necessário porque a sede é em São Paulo (≈140 km).
A41: 5. CUSTOS VARIÁVEIS (por km rodado)
A42: Diesel S10 — preço médio bomba (SP) | B42: 6.2 | C42: R$/litro | D42: ESTIMATIVA (ANP, SP, set/2026). Atualize com a cotação do posto/fornecedor.
A43: Consumo em ASFALTO — ônibus 59 lug. | B43: 2.9 | C43: km/litro | D43: ESTIMATIVA para ônibus urbano/rodoviário leve com paradas.
A44: Consumo em TERRA (estrada rural) | B44: 2.4 | C44: km/litro | D44: ESTIMATIVA: piso de terra reduz ~15–20% o rendimento.
A45: ARLA 32 | B45: 0.07 | C45: R$/km | D45: ≈5% do volume de diesel × R$ 4,00/l.
...

Sheet Linhas
A1: DADOS DAS LINHAS — extraídos do Anexo II (Modelo de Proposta) do PE 036/2026 e da planilha de lances Licita+
A2: Azul: dados do edital (não alterar salvo erro de leitura). Asfalto = km/dia − terra (fórmula). Preço de referência = planilha 'Licita+ Brasil - Planilha de Lances Iniciais'.
A4: Linha | B4: KM total (edital) | C4: KM por dia | D4: KM terra / dia | E4: KM asfalto / dia | F4: % terra | G4: Períodos | H4: Noturno? | I4: Ônibus | J4: Motoristas | K4: Monitoras | L4: Vencimento (edital) | M4: Preço ref. (R$/km) | N4: Valor ref. total (R$)
A5: 1 | B5: 27160 | C5: 135.8 | D5: 44.1 | E5: =C5-D5 -> 91.7 | F5: =IF(C5=0,0,D5/C5) -> 0.32474227 | G5: Matutino, Vespertino e Noturno | H5: S | I5: 1 | J5: 1 | K5: 1 | L5: 10/12/2026 | M5: 23.54 | N5: =B5*M5 -> 639346.4
A6: 2 | B6: 21760 | C6: 108.8 | D6: 14.72 | E6: =C6-D6 -> 94.08 | F6: =IF(C6=0,0,D6/C6) -> 0.13529412 | G6: Matutino e Vespertino | H6: N | I6: 1 | J6: 1 | K6: 0 | L6: 10/12/2026 | M6: 23.55 | N6: =B6*M6 -> 512448
A7: 3 | B7: 17520 | C7: 87.6 | D7: 33.08 | E7: =C7-D7 -> 54.52 | F7: =IF(C7=0,0,D7/C7) -> 0.37762557 | G7: Matutino e Vespertino (2 itin.) | H7: N | I7: 2 | J7: 2 | K7: 2 | L7: 24/04/2027 | M7: 25.66 | N7: =B7*M7 -> 449563.2
A8: 4 | B8: 29120 | C8: 145.6 | D8: 30.64 | E8: =C8-D8 -> 114.96 | F8: =IF(C8=0,0,D8/C8) -> 0.21043956 | G8: Matutino, Vespertino e Noturno | H8: S | I8: 1 | J8: 1 | K8: 1 | L8: 10/12/2026 | M8: 27.6 | N8: =B8*M8 -> 803712
A9: 5 | B9: 20160 | C9: 100.8 | D9: 18.56 | E9: =C9-D9 -> 82.24 | F9: =IF(C9=0,0,D9/C9) -> 0.18412698 | G9: Matutino e Vespertino | H9: N | I9: 1 | J9: 1 | K9: 1 | L9: 10/12/2026 | M9: 25.5 | N9: =B9*M9 -> 514080
A10: 6 | B10: 32920 | C10: 164.6 | D10: 49.02 | E10: =C10-D10 -> 115.58 | F10: =IF(C10=0,0,D10/C10) -> 0.29781288 | G10: Matutino, Vespertino e Noturno | H10: S | I10: 1 | J10: 1 | K10: 1 | L10: 10/12/2026 | M10: 26.36 | N10: =B10*M10 -> 867771.2
A11: 7 | B11: 16720 | C11: 83.6 | D11: 44.32 | E11: =C11-D11 -> 39.28 | F11: =IF(C11=0,0,D11/C11) -> 0.53014354 | G11: Matutino e Vespertino | H11: N | I11: 1 | J11: 1 | K11: 1 | L11: 10/12/2026 | M11: 25.49 | N11: =B11*M11 -> 426192.8
A12: 8 | B12: 14880 | C12: 74.4 | D12: 23.74 | E12: =C12-D12 -> 50.66 | F12: =IF(C12=0,0,D12/C12) -> 0.31908602 | G12: Matutino e Vespertino | H12: N | I12: 1 | J12: 1 | K12: 1 | L12: 24/04/2027 | M12: 27.8 | N12: =B12*M12 -> 413664
A13: 9 | B13: 11120 | C13: 55.6 | D13: 0 | E13: =C13-D13 -> 55.6 | F13: =IF(C13=0,0,D13/C13) -> 0 | G13: Matutino e Vespertino | H13: N | I13: 1 | J13: 1 | K13: 1 | L13: 24/04/2027 | M13: 28.9 | N13: =B13*M13 -> 321368
A14: TOTAL | B14: =SUM(B5:B13) -> 191360 | I14: =SUM(I5:I13) -> 10 | J14: =SUM(J5:J13) -> 10 | K14: =SUM(K5:K13) -> 9 | N14: =SUM(N5:N13) -> 4948145.6
A16: Observações de leitura do edital:
A17: • Linha 02: o Anexo II não menciona monitora (apenas 1 motorista por período) — confirmar no Termo de Referência; se houver monitora, altere a coluna K.
A18: • Linha 03: 2 itinerários simultâneos → 2 ônibus, 2 motoristas e 2 monitoras (87,6 km/dia somados).
A19: • Linhas 01, 04 e 06: período noturno até 23h00 — custo de pessoal recebe o fator de jornada estendida (Premissas).
A20: • Linha 04 e 06/08: no edital a soma terra + asfalto não bate exatamente com o total do dia; adotou-se terra do edital e asfalto = total − terra.
A21: • Linha 09: 100% asfalto. Linha 06: maior km terra (49 km/dia), o que eleva combustível, pneus e manutenção.
A22: • Vencimentos diferentes (10/12/2026 e 24/04/2027) — o edital mesmo assim quantifica 200 dias letivos em todas as linhas.

Sheet Custo por Linha
A1: COMPOSIÇÃO DE CUSTO E PREÇO POR LINHA (todas as células são fórmulas — altere apenas Premissas e Linhas)
A2: Preço/km proposto = custo total ÷ (1 − lucro − tributos) ÷ km do edital, arredondado em 2 casas (exigência do edital).
A4: Linha | B4: KM edital | C4: KM rodado c/ km morto | D4: Pessoal /mês (R$) | E4: Veículo /mês (R$) | F4: Custo fixo total (R$) | G4: Diesel (R$/km) | H4: Outros variáveis (R$/km) | I4: Variável total (R$/km) | J4: Custo variável total (R$) | K4: Custo direto (R$) | L4: Overhead (R$) | M4: Custo total (R$) | N4: Custo /km (R$) | O4: Preço /km PROPOSTO (R$) | P4: Valor total proposto (R$) | Q4: Lucro líquido (R$) | R4: Preço ref. (R$/km) | S4: Δ vs. referência | T4: Valor ref. total (R$) | U4: Fixo /km | V4: Variável /km
A5: =Linhas!A5 -> 1 | B5: =Linhas!B5 -> 27160 | C5: =B5*(1+Premissas!$B$20) -> 29876 | D5: =Linhas!J5*Premissas!$B$24*(1+Premissas!$B$26)*IF(Linhas!H5="S",Premissas!$B$27,1)+Linhas!K5*Premissas!$B$25*(1+Premissas!$B$26)+(Linhas!J5+Linhas!K5)*(Premissas!$B$28+Premissas!$B$29) -> 12254 | E5: =Linhas!I5*(1+Premissas!$B$21)*(Premissas!$B$32*(Premissas!$B$33+Premissas!$B$34)/12+Premissas!$B$35+Premissas!$B$36/12+Premissas!$B$37+Premissas!$B$38/12)+Linhas!I5*Premissas!$B$39 -> 8899.8333 | F5: =(D5+E5)*Premissas!$B$19 -> 253846 | G5: =Premissas!$B$42*((1-Linhas!F5)/Premissas!$B$43+Linhas!F5/Premissas!$B$44) -> 2.282572 | H5: =Premissas!$B$45+Premissas!$B$50+(1-Linhas!F5)*(Premissas!$B$46+Premissas!$B$48)+Linhas!F5*(Premissas!$B$47+Premissas!$B$49) -> 1.5123711 | I5: =G5+H5 -> 3.7949431 | J5: =I5*C5 -> 113377.72 | K5: =F5+J5 -> 367223.72 | L5: =K5*Premissas!$B$53 -> 29377.898 | M5: =K5+L5 -> 396601.62 | N5: =IF(B5=0,0,M5/B5) -> 14.602416 | O5: =IF(B5=0,0,ROUNDUP(M5/(1-Premissas!$B$54-Premissas!$B$60)/B5,2)) -> 18.47 | P5: =O5*B5 -> 501645.2 | Q5: =P5*(1-Premissas!$B$60)-M5 -> 50213.761 | R5: =Linhas!M5 -> 23.54 | S5: =IF(R5=0,0,O5/R5-1) -> -0.21537808 | T5: =Linhas!N5 -> 639346.4 | U5: =IF(B5=0,0,F5/B5) -> 9.3463181 | V5: =IF(B5=0,0,J5/B5) -> 4.1744374
A6: =Linhas!A6 -> 2 | B6: =Linhas!B6 -> 21760 | C6: =B6*(1+Premissas!$B$20) -> 23936 | D6: =Linhas!J6*Premissas!$B$24*(1+Premissas!$B$26)*IF(Linhas!H6="S",Premissas!$B$27,1)+Linhas!K6*Premissas!$B$25*(1+Premissas!$B$26)+(Linhas!J6+Linhas!K6)*(Premissas!$B$28+Premissas!$B$29) -> 6280 | E6: =Linhas!I6*(1+Premissas!$B$21)*(Premissas!$B$32*(Premissas!$B$33+Premissas!$B$34)/12+Premissas!$B$35+Premissas!$B$36/12+Premissas!$B$37+Premissas!$B$38/12)+Linhas!I6*Premissas!$B$39 -> 8899.8333 | F6: =(D6+E6)*Premissas!$B$19 -> 182158 | G6: =Premissas!$B$42*((1-Linhas!F6)/Premissas!$B$43+Linhas!F6/Premissas!$B$44) -> 2.1981913 | H6: =Premissas!$B$45+Premissas!$B$50+(1-Linhas!F6)*(Premissas!$B$46+Premissas!$B$48)+Linhas!F6*(Premissas!$B$47+Premissas!$B$49) -> 1.4176471 | I6: =G6+H6 -> 3.6158384 | J6: =I6*C6 -> 86548.708 | K6: =F6+J6 -> 268706.71 | L6: =K6*Premissas!$B$53 -> 21496.537 | M6: =K6+L6 -> 290203.24 | N6: =IF(B6=0,0,M6/B6) -> 13.336546 | O6: =IF(B6=0,0,ROUNDUP(M6/(1-Premissas!$B$54-Premissas!$B$60)/B6,2)) -> 16.87 | P6: =O6*B6 -> 367091.2 | Q6: =P6*(1-Premissas!$B$60)-M6 -> 36764.887 | R6: =Linhas!M6 -> 23.55 | S6: =IF(R6=0,0,O6/R6-1) -> -0.2836518 | T6: =Linhas!N6 -> 512448 | U6: =IF(B6=0,0,F6/B6) -> 8.3712316 | V6: =IF(B6=0,0,J6/B6) -> 3.9774222
A7: =Linhas!A7 -> 3 | B7: =Linhas!B7 -> 17520 | C7: =B7*(1+Premissas!$B$20) -> 19272 | D7: =Linhas!J7*Premissas!$B$24*(1+Premissas!$B$26)*IF(Linhas!H7="S",Premissas!$B$27,1)+Linhas!K7*Premissas!$B$25*(1+Premissas!$B$26)+(Linhas!J7+Linhas!K7)*(Premissas!$B$28+Premissas!$B$29) -> 20700 | E7: =Linhas!I7*(1+Premissas!$B$21)*(Premissas!$B$32*(Premissas!$B$33+Premissas!$B$34)/12+Premissas!$B$35+Premissas!$B$36/12+Premissas!$B$37+Premissas!$B$38/12)+Linhas!I7*Premissas!$B$39 -> 17799.667 | F7: =(D7+E7)*Premissas!$B$19 -> 461996 | G7: =Premissas!$B$42*((1-Linhas!F7)/Premissas!$B$43+Linhas!F7/Premissas!$B$44) -> 2.3061263 | H7: =Premissas!$B$45+Premissas!$B$50+(1-Linhas!F7)*(Premissas!$B$46+Premissas!$B$48)+Linhas!F7*(Premissas!$B$47+Premissas!$B$49) -> 1.5388128 | I7: =G7+H7 -> 3.8449391 | J7: =I7*C7 -> 74099.667 | K7: =F7+J7 -> 536095.67 | L7: =K7*Premissas!$B$53 -> 42887.653 | M7: =K7+L7 -> 578983.32 | N7: =IF(B7=0,0,M7/B7) -> 33.046993 | O7: =IF(B7=0,0,ROUNDUP(M7/(1-Premissas!$B$54-Premissas!$B$60)/B7,2)) -> 41.8 | P7: =O7*B7 -> 732336 | Q7: =P7*(1-Premissas!$B$60)-M7 -> 73308.355 | R7: =Linhas!M7 -> 25.66 | S7: =IF(R7=0,0,O7/R7-1) -> 0.62899454 | T7: =Linhas!N7 -> 449563.2 | U7: =IF(B7=0,0,F7/B7) -> 26.369635 | V7: =IF(B7=0,0,J7/B7) -> 4.229433
A8: =Linhas!A8 -> 4 | B8: =Linhas!B8 -> 29120 | C8: =B8*(1+Premissas!$B$20) -> 32032 | D8: =Linhas!J8*Premissas!$B$24*(1+Premissas!$B$26)*IF(Linhas!H8="S",Premissas!$B$27,1)+Linhas!K8*Premissas!$B$25*(1+Premissas!$B$26)+(Linhas!J8+Linhas!K8)*(Premissas!$B$28+Premissas!$B$29) -> 12254 | E8: =Linhas!I8*(1+Premissas!$B$21)*(Premissas!$B$32*(Premissas!$B$33+Premissas!$B$34)/12+Premissas!$B$35+Premissas!$B$36/12+Premissas!$B$37+Premissas!$B$38/12)+Linhas!I8*Premissas!$B$39 -> 8899.8333 | F8: =(D8+E8)*Premissas!$B$19 -> 253846 | G8: =Premissas!$B$42*((1-Linhas!F8)/Premissas!$B$43+Linhas!F8/Premissas!$B$44) -> 2.2316613 | H8: =Premissas!$B$45+Premissas!$B$50+(1-Linhas!F8)*(Premissas!$B$46+Premissas!$B$48)+Linhas!F8*(Premissas!$B$47+Premissas!$B$49) -> 1.4552198 | I8: =G8+H8 -> 3.6868811 | J8: =I8*C8 -> 118098.17 | K8: =F8+J8 -> 371944.17 | L8: =K8*Premissas!$B$53 -> 29755.534 | M8: =K8+L8 -> 401699.71 | N8: =IF(B8=0,0,M8/B8) -> 13.794633 | O8: =IF(B8=0,0,ROUNDUP(M8/(1-Premissas!$B$54-Premissas!$B$60)/B8,2)) -> 17.45 | P8: =O8*B8 -> 508144 | Q8: =P8*(1-Premissas!$B$60)-M8 -> 50904.152 | R8: =Linhas!M8 -> 27.6 | S8: =IF(R8=0,0,O8/R8-1) -> -0.36775362 | T8: =Linhas!N8 -> 803712 | U8: =IF(B8=0,0,F8/B8) -> 8.717239 | V8: =IF(B8=0,0,J8/B8) -> 4.0555692
A9: =Linhas!A9 -> 5 | B9: =Linhas!B9 -> 20160 | C9: =B9*(1+Premissas!$B$20) -> 22176 | D9: =Linhas!J9*Premissas!$B$24*(1+Premissas!$B$26)*IF(Linhas!H9="S",Premissas!$B$27,1)+Linhas!K9*Premissas!$B$25*(1+Premissas!$B$26)+(Linhas!J9+Linhas!K9)*(Premissas!$B$28+Premissas!$B$29) -> 10350 | E9: =Linhas!I9*(1+Premissas!$B$21)*(Premissas!$B$32*(Premissas!$B$33+Premissas!$B$34)/12+Premissas!$B$35+Premissas!$B$36/12+Premissas!$B$37+Premissas!$B$38/12)+Linhas!I9*Premissas!$B$39 -> 8899.8333 | F9: =(D9+E9)*Premissas!$B$19 -> 230998 | G9: =Premissas!$B$42*((1-Linhas!F9)/Premissas!$B$43+Linhas!F9/Premissas!$B$44) -> 2.2199416 | H9: =Premissas!$B$45+Premissas!$B$50+(1-Linhas!F9)*(Premissas!$B$46+Premissas!$B$48)+Linhas!F9*(Premissas!$B$47+Premissas!$B$49) -> 1.4420635 | I9: =G9+H9 -> 3.6620051 | J9: =I9*C9 -> 81208.625 | K9: =F9+J9 -> 312206.63 | L9: =K9*Premissas!$B$53 -> 24976.53 | M9: =K9+L9 -> 337183.16 | N9: =IF(B9=0,0,M9/B9) -> 16.725355 | O9: =IF(B9=0,0,ROUNDUP(M9/(1-Premissas!$B$54-Premissas!$B$60)/B9,2)) -> 21.16 | P9: =O9*B9 -> 426585.6 | Q9: =P9*(1-Premissas!$B$60)-M9 -> 42776.639 | R9: =Linhas!M9 -> 25.5 | S9: =IF(R9=0,0,O9/R9-1) -> -0.17019608 | T9: =Linhas!N9 -> 514080 | U9: =IF(B9=0,0,F9/B9) -> 11.458234 | V9: =IF(B9=0,0,J9/B9) -> 4.0282056
A10: =Linhas!A10 -> 6 | B10: =Linhas!B10 -> 32920 | C10: =B10*(1+Premissas!$B$20) -> 36212 | D10: =Linhas!J10*Premissas!$B$24*(1+Premissas!$B$26)*IF(Linhas!H10="S",Premissas!$B$27,1)+Linhas!K10*Premissas!$B$25*(1+Premissas!$B$26)+(Linhas!J10+Linhas!K10)*(Premissas!$B$28+Premissas!$B$29) -> 12254 | E10: =Linhas!I10*(1+Premissas!$B$21)*(Premissas!$B$32*(Premissas!$B$33+Premissas!$B$34)/12+Premissas!$B$35+Premissas!$B$36/12+Premissas!$B$37+Premissas!$B$38/12)+Linhas!I10*Premissas!$B$39 -> 8899.8333 | F10: =(D10+E10)*Premissas!$B$19 -> 253846 | G10: =Premissas!$B$42*((1-Linhas!F10)/Premissas!$B$43+Linhas!F10/Premissas!$B$44) -> 2.2705776 | H10: =Premissas!$B$45+Premissas!$B$50+(1-Linhas!F10)*(Premissas!$B$46+Premissas!$B$48)+Linhas!F10*(Premissas!$B$47+Premissas!$B$49) -> 1.4989064 | I10: =G10+H10 -> 3.769484 | J10: =I10*C10 -> 136500.56 | K10: =F10+J10 -> 390346.56 | L10: =K10*Premissas!$B$53 -> 31227.724 | M10: =K10+L10 -> 421574.28 | N10: =IF(B10=0,0,M10/B10) -> 12.806023 | O10: =IF(B10=0,0,ROUNDUP(M10/(1-Premissas!$B$54-Premissas!$B$60)/B10,2)) -> 16.2 | P10: =O10*B10 -> 533304 | Q10: =P10*(1-Premissas!$B$60)-M10 -> 53439.593 | R10: =Linhas!M10 -> 26.36 | S10: =IF(R10=0,0,O10/R10-1) -> -0.38543247 | T10: =Linhas!N10 -> 867771.2 | U10: =IF(B10=0,0,F10/B10) -> 7.7109964 | V10: =IF(B10=0,0,J10/B10) -> 4.1464324
A11: =Linhas!A11 -> 7 | B11: =Linhas!B11 -> 16720 | C11: =B11*(1+Premissas!$B$20) -> 18392 | D11: =Linhas!J11*Premissas!$B$24*(1+Premissas!$B$26)*IF(Linhas!H11="S",Premissas!$B$27,1)+Linhas!K11*Premissas!$B$25*(1+Premissas!$B$26)+(Linhas!J11+Linhas!K11)*(Premissas!$B$28+Premissas!$B$29) -> 10350 | E11: =Linhas!I11*(1+Premissas!$B$21)*(Premissas!$B$32*(Premissas!$B$33+Premissas!$B$34)/12+Premissas!$B$35+Premissas!$B$36/12+Premissas!$B$37+Premissas!$B$38/12)+Linhas!I11*Premissas!$B$39 -> 8899.8333 | F11: =(D11+E11)*Premissas!$B$19 -> 230998 | G11: =Premissas!$B$42*((1-Linhas!F11)/Premissas!$B$43+Linhas!F11/Premissas!$B$44) -> 2.3740582 | H11: =Premissas!$B$45+Premissas!$B$50+(1-Linhas!F11)*(Premissas!$B$46+Premissas!$B$48)+Linhas!F11*(Premissas!$B$47+Premissas!$B$49) -> 1.6150718 | I11: =G11+H11 -> 3.98913 | J11: =I11*C11 -> 73368.078 | K11: =F11+J11 -> 304366.08 | L11: =K11*Premissas!$B$53 -> 24349.286 | M11: =K11+L11 -> 328715.36 | N11: =IF(B11=0,0,M11/B11) -> 19.66001 | O11: =IF(B11=0,0,ROUNDUP(M11/(1-Premissas!$B$54-Premissas!$B$60)/B11,2)) -> 24.87 | P11: =O11*B11 -> 415826.4 | Q11: =P11*(1-Premissas!$B$60)-M11 -> 41661.21 | R11: =Linhas!M11 -> 25.49 | S11: =IF(R11=0,0,O11/R11-1) -> -0.024323264 | T11: =Linhas!N11 -> 426192.8 | U11: =IF(B11=0,0,F11/B11) -> 13.81567 | V11: =IF(B11=0,0,J11/B11) -> 4.388043
A12: =Linhas!A12 -> 8 | B12: =Linhas!B12 -> 14880 | C12: =B12*(1+Premissas!$B$20) -> 16368 | D12: =Linhas!J12*Premissas!$B$24*(1+Premissas!$B$26)*IF(Linhas!H12="S",Premissas!$B$27,1)+Linhas!K12*Premissas!$B$25*(1+Premissas!$B$26)+(Linhas!J12+Linhas!K12)*(Premissas!$B$28+Premissas!$B$29) -> 10350 | E12: =Linhas!I12*(1+Premissas!$B$21)*(Premissas!$B$32*(Premissas!$B$33+Premissas!$B$34)/12+Premissas!$B$35+Premissas!$B$36/12+Premissas!$B$37+Premissas!$B$38/12)+Linhas!I12*Premissas!$B$39 -> 8899.8333 | F12: =(D12+E12)*Premissas!$B$19 -> 230998 | G12: =Premissas!$B$42*((1-Linhas!F12)/Premissas!$B$43+Linhas!F12/Premissas!$B$44) -> 2.2800527 | H12: =Premissas!$B$45+Premissas!$B$50+(1-Linhas!F12)*(Premissas!$B$46+Premissas!$B$48)+Linhas!F12*(Premissas!$B$47+Premissas!$B$49) -> 1.509543 | I12: =G12+H12 -> 3.7895957 | J12: =I12*C12 -> 62028.102 | K12: =F12+J12 -> 293026.1 | L12: =K12*Premissas!$B$53 -> 23442.088 | M12: =K12+L12 -> 316468.19 | N12: =IF(B12=0,0,M12/B12) -> 21.268024 | O12: =IF(B12=0,0,ROUNDUP(M12/(1-Premissas!$B$54-Premissas!$B$60)/B12,2)) -> 26.9 | P12: =O12*B12 -> 400272 | Q12: =P12*(1-Premissas!$B$60)-M12 -> 40054.08 | R12: =Linhas!M12 -> 27.8 | S12: =IF(R12=0,0,O12/R12-1) -> -0.032374101 | T12: =Linhas!N12 -> 413664 | U12: =IF(B12=0,0,F12/B12) -> 15.524059 | V12: =IF(B12=0,0,J12/B12) -> 4.1685553
A13: =Linhas!A13 -> 9 | B13: =Linhas!B13 -> 11120 | C13: =B13*(1+Premissas!$B$20) -> 12232 | D13: =Linhas!J13*Premissas!$B$24*(1+Premissas!$B$26)*IF(Linhas!H13="S",Premissas!$B$27,1)+Linhas!K13*Premissas!$B$25*(1+Premissas!$B$26)+(Linhas!J13+Linhas!K13)*(Premissas!$B$28+Premissas!$B$29) -> 10350 | E13: =Linhas!I13*(1+Premissas!$B$21)*(Premissas!$B$32*(Premissas!$B$33+Premissas!$B$34)/12+Premissas!$B$35+Premissas!$B$36/12+Premissas!$B$37+Premissas!$B$38/12)+Linhas!I13*Premissas!$B$39 -> 8899.8333 | F13: =(D13+E13)*Premissas!$B$19 -> 230998 | G13: =Premissas!$B$42*((1-Linhas!F13)/Premissas!$B$43+Linhas!F13/Premissas!$B$44) -> 2.137931 | H13: =Premissas!$B$45+Premissas!$B$50+(1-Linhas!F13)*(Premissas!$B$46+Premissas!$B$48)+Linhas!F13*(Premissas!$B$47+Premissas!$B$49) -> 1.35 | I13: =G13+H13 -> 3.487931 | J13: =I13*C13 -> 42664.372 | K13: =F13+J13 -> 273662.37 | L13: =K13*Premissas!$B$53 -> 21892.99 | M13: =K13+L13 -> 295555.36 | N13: =IF(B13=0,0,M13/B13) -> 26.57872 | O13: =IF(B13=0,0,ROUNDUP(M13/(1-Premissas!$B$54-Premissas!$B$60)/B13,2)) -> 33.62 | P13: =O13*B13 -> 373854.4 | Q13: =P13*(1-Premissas!$B$60)-M13 -> 37436.752 | R13: =Linhas!M13 -> 28.9 | S13: =IF(R13=0,0,O13/R13-1) -> 0.1633218 | T13: =Linhas!N13 -> 321368 | U13: =IF(B13=0,0,F13/B13) -> 20.773201 | V13: =IF(B13=0,0,J13/B13) -> 3.8367241
A14: TOTAL | B14: =SUM(B5:B13) -> 191360 | C14: =SUM(C5:C13) -> 210496 | F14: =SUM(F5:F13) -> 2329684 | J14: =SUM(J5:J13) -> 787894 | K14: =SUM(K5:K13) -> 3117578 | L14: =SUM(L5:L13) -> 249406.24 | M14: =SUM(M5:M13) -> 3366984.2 | N14: =IF(B14=0,0,M14/B14) -> 17.595026 | O14: =IF(B14=0,0,P14/B14) -> 22.256787 | P14: =SUM(P5:P13) -> 4259058.8 | Q14: =SUM(Q5:Q13) -> 426559.43 | S14: =IF(T14=0,0,P14/T14-1) -> -0.13926163 | T14: =SUM(T5:T13) -> 4948145.6
A16: RESUMO
A17: Valor total da proposta (9 linhas) | F17: =P14 -> 4259058.8
A18: Valor total de referência (Licita+) | F18: =T14 -> 4948145.6
A19: Proposta vs. referência | F19: =S14 -> -0.13926163
A20: Custo total estimado | F20: =M14 -> 3366984.2
A21: Lucro líquido estimado (após tributos) | F21: =Q14 -> 426559.43
A22: Margem líquida sobre faturamento | F22: =IF(P14=0,0,Q14/P14) -> 0.10015345
A23: Preço médio proposto (R$/km) | F23: =O14 -> 22.256787
A24: Preço mínimo p/ empatar custo (R$/km, lucro zero) | F24: =IF(B14=0,0,M14/(1-Premissas!$B$60)/B14) -> 19.754156
A25: Frota necessária (ônibus, sem reserva) | F25: =Linhas!I14 -> 10
A26: Motoristas / Monitoras | F26: =Linhas!J14&" / "&Linhas!K14 -> 10 / 9

Sheet Proposta (Anexo II)
A1: ANEXO II — MODELO DE PROPOSTA — PREGÃO ELETRÔNICO N° 036/2026 — PREFEITURA MUNICIPAL DA ESTÂNCIA TURÍSTICA DE HOLAMBRA
A2: Objeto: Contratação de pessoas jurídicas (empresa especializada em transporte escolar) para a prestação de serviços de transporte escolar para zona rural e urbana para os alunos do Município de Holambra, veículos utilizados: ônibus, conforme condições estabelecidas no Termo de Referência.
A4: DADOS DO LICITANTE
A5: DENOMINAÇÃO: | B5: =Premissas!$B$6 -> AZUL TRANSPORTES E TURISMO LTDA
A6: ENDEREÇO: | B6: =Premissas!$B$7 -> 0
A7: CNPJ: | B7: =Premissas!$B$8 -> 10.764.533/0001-01
A8: TELEFONE: | B8: =Premissas!$B$9 -> 0
A9: E-MAIL: | B9: =Premissas!$B$10 -> 0
A11: RESPONSÁVEL PELA ASSINATURA DO CONTRATO
A12: NOME: | B12: =Premissas!$B$11 -> 0
A13: RG: | B13: =Premissas!$B$12 -> 0
A14: CPF: | B14: =Premissas!$B$13 -> 0
A15: E-MAIL: | B15: =Premissas!$B$10 -> 0
A16: CARGO: | B16: =Premissas!$B$14 -> 0
A18: LINHAS/ROTAS E SEU ITINERÁRIO
A19: LINHA/ ROTA | B19: QTD. | C19: UNID. | D19: DESCRIÇÃO DA LINHA | E19: PREÇO POR KM RODADO | F19: VALOR TOTAL DA LINHA
A20: ='Custo por Linha'!A5 -> 1 | B20: ='Custo por Linha'!B5 -> 27160 | C20: KM | D20: LINHA 01 – Matutino, Vespertino e Noturno – 135,8 km/dia – veículo mín. 59 lugares – 1 motorista, 1 monitora – seg. a sex. – venc. 10/12/2026 | E20: ='Custo por Linha'!O5 -> 18.47 | F20: =B20*E20 -> 501645.2
A21: ='Custo por Linha'!A6 -> 2 | B21: ='Custo por Linha'!B6 -> 21760 | C21: KM | D21: LINHA 02 – Matutino e Vespertino – 108,8 km/dia – veículo mín. 59 lugares – 1 motorista – seg. a sex. – venc. 10/12/2026 | E21: ='Custo por Linha'!O6 -> 16.87 | F21: =B21*E21 -> 367091.2
A22: ='Custo por Linha'!A7 -> 3 | B22: ='Custo por Linha'!B7 -> 17520 | C22: KM | D22: LINHA 03 – Itinerários 1 e 2 – Matutino e Vespertino – 87,6 km/dia – 2 veículos mín. 59 lugares – 2 motoristas, 2 monitoras – seg. a sex. – venc. 24/04/2027 | E22: ='Custo por Linha'!O7 -> 41.8 | F22: =B22*E22 -> 732336
A23: ='Custo por Linha'!A8 -> 4 | B23: ='Custo por Linha'!B8 -> 29120 | C23: KM | D23: LINHA 04 – Matutino, Vespertino e Noturno – 145,6 km/dia – veículo mín. 59 lugares – 1 motorista, 1 monitora – seg. a sex. – venc. 10/12/2026 | E23: ='Custo por Linha'!O8 -> 17.45 | F23: =B23*E23 -> 508144
A24: ='Custo por Linha'!A9 -> 5 | B24: ='Custo por Linha'!B9 -> 20160 | C24: KM | D24: LINHA 05 – Matutino e Vespertino – 100,8 km/dia – veículo mín. 59 lugares – 1 motorista, 1 monitora – seg. a sex. – venc. 10/12/2026 | E24: ='Custo por Linha'!O9 -> 21.16 | F24: =B24*E24 -> 426585.6
A25: ='Custo por Linha'!A10 -> 6 | B25: ='Custo por Linha'!B10 -> 32920 | C25: KM | D25: LINHA 06 – Matutino, Vespertino e Noturno – 164,6 km/dia – veículo mín. 59 lugares – 1 motorista, 1 monitora – seg. a sex. – venc. 10/12/2026 | E25: ='Custo por Linha'!O10 -> 16.2 | F25: =B25*E25 -> 533304
A26: ='Custo por Linha'!A11 -> 7 | B26: ='Custo por Linha'!B11 -> 16720 | C26: KM | D26: LINHA 07 – Matutino e Vespertino – 83,6 km/dia – veículo mín. 59 lugares – 1 motorista, 1 monitora – seg. a sex. – venc. 10/12/2026 | E26: ='Custo por Linha'!O11 -> 24.87 | F26: =B26*E26 -> 415826.4
A27: ='Custo por Linha'!A12 -> 8 | B27: ='Custo por Linha'!B12 -> 14880 | C27: KM | D27: LINHA 08 – Matutino e Vespertino – 74,4 km/dia – veículo mín. 59 lugares – 1 motorista, 1 monitora – seg. a sex. – venc. 24/04/2027 | E27: ='Custo por Linha'!O12 -> 26.9 | F27: =B27*E27 -> 400272
A28: ='Custo por Linha'!A13 -> 9 | B28: ='Custo por Linha'!B13 -> 11120 | C28: KM | D28: LINHA 09 – Matutino e Vespertino – 55,6 km/dia – veículo mín. 59 lugares – 1 motorista, 1 monitora – seg. a sex. – venc. 24/04/2027 | E28: ='Custo por Linha'!O13 -> 33.62 | F28: =B28*E28 -> 373854.4
D29: VALOR GLOBAL DA PROPOSTA | F29: =SUM(F20:F28) -> 4259058.8
A31: CONDIÇÃO DE PAGAMENTO: 30 (trinta) dias, após a liquidação e aceite pelos gestores do contrato.
A32: VALIDADE DA PROPOSTA: 60 (SESSENTA) DIAS
A33: Os valores que ultrapassarem 02 (duas) casas decimais após a vírgula serão desconsiderados para fins de apuração do preço final.
A34: DECLARAMOS QUE estamos de acordo com os termos do Edital, e acatamos suas determinações, bem como informamos que nos preços propostos estão inclusos todos os custos diretos e indiretos, lucros e demais contribuições pertinentes de nossa responsabilidade, sem qualquer exceção, constituindo-se os referidos preços unitários nas únicas contraprestações da PREFEITURA MUNICIPAL DE HOLAMBRA pelas efetivas prestações de serviços de transporte de alunos, sob nossa conta e risco.
A35: DECLARAMOS QUE os serviços ofertados atendem a todas as condições fixadas nas normas técnicas especificadas no edital.
A36: DECLARAMOS QUE nenhum direito a indenização ou a reembolso de quaisquer despesas nos será devido, caso nossa proposta não seja aceita pela PREFEITURA MUNICIPAL DE HOLAMBRA.
A37: DECLARAMOS QUE CONCORDAMOS integralmente com as condições estipuladas na presente licitação e, que caso vencedores, nos submeteremos ao cumprimento de seus termos.
A39: =Premissas!$B$15 -> São Paulo, 28 de setembro de 2026
A41: _____________________________________
A42: =Premissas!$B$11&" — "&Premissas!$B$14 -> —
A43: =Premissas!$B$6&" — CNPJ "&Premissas!$B$8 -> AZUL TRANSPORTES E TURISMO LTDA — CNPJ 10.764.533/0001-01
