Workbook

Sheet Regras do Edital
A1: REGRAS DO EDITAL / TR COM IMPACTO NO CUSTO E NA PARTICIPAÇÃO — PE 089/2026-SERMALI
A3: Tema | B3: Regra (fonte) | C3: Impacto no custo / risco | D3: Onde está na planilha
A4: Sessão / plataforma | B4: 28/09/2026 09h, Comprasgov (UASG 987885). Lote único com 2 itens; menor preço por lote; disputa ABERTA; lance mínimo R$ 0,20; lance por valor unitário com 2 casas. | C4: Mesmo preço/km nos dois itens é o mais simples; o julgamento é pelo valor do lote. | D4: Cenários!B4
A5: Preço máximo | B5: R$ 11,11/km em ambos os itens; valor total R$ 4.906.176 (374.400 + 67.200 km/ano). Cotações de referência: R$ 10,71 a R$ 11,44 (Chapecó, Rondonópolis, Alto Garças). | C5: Proposta acima do teto é desclassificada; abaixo do piso de custo pode sofrer diligência de exequibilidade (edital 70). | D5: Composição!B/C pmax
A6: Pagamento só por km útil | B6: SRP: paga-se exclusivamente km útil rodado e validado por telemetria + lista de presença eletrônica (TR 3.6, 8.22, 9.31, 10.2–10.7). Sem indenização por ociosidade (TR 3.9, 10.3). | C6: Custos fixos (folha, vans) não têm garantia de diluição. Fase 1 = só CDR local + UBS; rotas externas na Fase 2. | D6: Premissas.utilização; Cenários
A7: Ponto de partida do km útil | B7: Pacientes: Central de Veículos (R. Francisco Dal Negro, 2684). Servidores: Paço Municipal (TR 8.14). Garagem pública vedada (TR 8.27). | C7: Km garagem→ponto de partida e retorno vazio não são pagos → km morto + base própria em SJP. | D7: Premissas.km_morto / garagem
A8: Frota | B8: Vans ≥15 lugares, ≤5 anos E ≤150.000 km, mínimo 6 vans na frota inicial, ajuste dinâmico de frota (TR 8.8–8.10); substituição em 2 h (quebra) / 48 h (avaria menor). | C8: Item 01 roda ~300 km/van/dia → ~94 mil km/ano: van usada estoura 150 mil km em 1–2 anos. Reserva técnica obrigatória na prática. | D8: Premissas.valor_van, deprec, reserva
A9: Jornada | B9: Hemodiálise: 3 turnos 06h–19h, seg. a SÁBADO, inclusive feriados (TR 8.2, 8.16); coleta domiciliar antes e entrega depois. Servidores: 07h–17h seg. a sex. (TR 8.25). | C9: Item 01 exige ~2 motoristas por van ou banco de horas; sábados e feriados = HE/adicional. | D9: Premissas.mot_por_van_hd, he
A10: Motoristas | B10: CNH D + EAR + curso CONTRAN transporte coletivo + curso primeiros socorros (TR 2.26–2.27); declaração de vinculação futura assinada pelos motoristas (Anexo VI); uniforme e crachá (TR 9.19); substituição em 2 h. | C10: Recrutamento LOCAL (RMC) antes da sessão para assinar o Anexo VI; custos de cursos e toxicológico. | D10: Premissas.sal_mot, epi
A11: Telemetria | B11: Rastreamento GPRS em 100% da frota no dia 1 + sistema HÍBRIDO GPRS/satélite em 60 dias (TR 2.21–2.23, 9.24–9.26); acesso web/app para fiscalização; relatório mensal de telemetria. | C11: Rastreador híbrido custa 2–3× o convencional; Ituran atual da Azul pode precisar de upgrade satelital. | D11: Premissas.telemetria
A12: Controle de embarque | B12: Registro biométrico/QR Code/app por passageiro integrado ao rastreador; Relatório Consolidado de Frequência mensal; sem registro não há pagamento do km (TR 9.27–9.31). | C12: Custo de app/dispositivo por van + treinamento; risco de glosa se o motorista não registrar. | D12: Premissas.embarque
A13: Seguro | B13: RCF-V mínimo: R$ 40 mil DM, R$ 100 mil DC, R$ 5 mil DMo (TR 9.17). Laudo técnico de frota em 5 dias úteis (TR 5.7). | C13: Apólice específica por van vinculada ao contrato. | D13: Premissas.seguro, laudo
A14: Insumos por conta da contratada | B14: Combustível, ARLA (notas arquivadas), lubrificantes, pneus, manutenção, seguros, taxas, licenciamento, alimentação e fardamento (TR 5.2, 8.6). | C14: Todos os insumos estão na composição; ARLA é obrigatório e fiscalizado. | D14: Premissas seção 5
... A20: Sanções | B20: Multa de 0,5% a 30% sobre o valor do objeto; impedimento de licitar. Vedada subcontratação do objeto principal (TR 5.3). | C20: Contingência de 3% sobre custo direto. | D20: Premissas.risco

Sheet Premissas
A1: PLANILHA DE CUSTOS — PREGÃO ELETRÔNICO 089/2026-SERMALI — SÃO JOSÉ DOS PINHAIS/PR — Transporte de pacientes SUS (hemodiálise) e servidores (vans ≥15 lug.)
A2: Legenda: azul = entrada editável · amarelo = preencher · preto = fórmula · verde = link de outra aba. Premissas de custo são ESTIMATIVAS DE MERCADO (Curitiba/RMC, set/2026) — troque pelos números reais da Azul Mob. Sessão: 28/09/2026 09h (Comprasgov, UASG 987885). Preço máximo: R$ 11,11/km nos 2 itens. Lote único, menor preço por lote, disputa aberta, lance mínimo R$ 0,20.
A4: Item | B4: Valor | C4: Unid. | D4: Observação / fonte / regra do edital
A5: 1. DADOS DO LICITANTE
A6: Razão social | B6: AZUL TRANSPORTES E TURISMO LTDA | D6: Nome fantasia Azul Mob.
A7: CNPJ | B7: 10.764.533/0001-01
A8: Endereço da sede | D8: PREENCHER (São Paulo/SP). Atenção: o edital exige certidão de tributos municipais de São José dos Pinhais também (TR 2.9).
A9: Representante legal (nome / RG / CPF) | D9: PREENCHER — assina proposta, Anexo VI (vinculação dos motoristas) e declaração de rastreamento.
A11: 2. PARÂMETROS DO CONTRATO (extraídos do edital / TR nº 225/2026)
A12: Vigência considerada | B12: 12 | C12: meses | D12: Ata 12 meses prorrogável; contrato 12 meses prorrogável até 10 anos (TR 4.6/4.7). Início após 05/12/2026 (TR 8.1).
A13: Dias de operação/mês — Item 01 hemodiálise | B13: 26 | C13: dias | D13: Segunda a SÁBADO, inclusive feriados (TR 8.2/8.16).
A14: Dias de operação/mês — Item 02 servidores | B14: 22 | C14: dias | D14: Segunda a sexta, 07h00–17h00 (TR 8.25).
A15: Utilização esperada do km máximo registrado | B15: 0.85 | C15: % | D15: RISCO-CHAVE: SRP paga só km útil validado (telemetria + presença). Fase 1 = só CDR local + UBS; rotas externas (Curitiba etc.) entram na Fase 2, gradualmente (TR 3.3–3.9). Sem indenização por ociosidade (TR 10.3). Use 0,7–1,0 para testar.
A16: Km improdutivo (garagem ↔ ponto de partida, retornos vazios) | B16: 0.15 | C16: % do km útil | D16: Km útil conta a partir da Central de Veículos (pacientes) ou Paço Municipal (servidores) — TR 8.14. Deslocamento da garagem própria até lá NÃO é pago; garagem pública é vedada (TR 8.27).
A17: Reserva técnica de frota | B17: 0.15 | C17: % da frota | D17: Substituição em até 2 h por quebra (TR 8.4) e 48 h por avaria menor (TR 9.18) → 1 van reserva para cada ~7. Frota inicial mínima: 6 vans (TR 8.8).
A19: 3. MÃO DE OBRA
A20: Salário base — motorista de van (CNH D + EAR + curso coletivo) | B20: 2950 | C20: R$/mês | D20: ESTIMATIVA CCT SETRANSP/SINDIMOC Curitiba-RMC 2026 (motorista de micro/van). Exige curso CONTRAN transporte coletivo + primeiros socorros (TR 2.26/2.27).
A21: Motoristas por van — Item 01 (3 turnos 06h–19h + coleta domiciliar) | B21: 1.8 | C21: motoristas/van | D21: Jornada útil ≈ 05h00–20h00 (15 h) → 2 motoristas por van ou 1 + escala. 1,8 = 2 motoristas com folgas compensadas por reserva. Sábado = jornada 44 h/sem.
A22: Motoristas por van — Item 02 (07h–17h, ociosa no meio do dia) | B22: 1 | C22: motoristas/van | D22: 1 motorista; horas de espera são jornada (TR 8.26 — veículo livre, mas pontualidade obrigatória).
A23: Horas extras / adicional (média sobre salário) | B23: 0.12 | C23: % | D23: Sábados, feriados (TR 8.2), atrasos de clínica. Estimativa.
A24: Encargos e provisões (INSS patronal, RAT, FGTS, férias+1/3, 13º, rescisão) | B24: 0.7 | C24: % | D24: Regime CLT, lucro presumido/real (não Simples). Folha deve ser apresentada com a NF (TR 10.16).
A25: Benefícios (VA/VR + cesta + seguro de vida + VT) | B25: 950 | C25: R$/mês por func. | D25: Curitiba/RMC: VA ~R$ 30/dia + VT (equipe local). Alimentação e fardamento são da contratada (TR 8.6).
A26: Uniforme, crachá, EPI, ASO, toxicológico, cursos | B26: 90 | C26: R$/mês por func. | D26: Uniforme + crachá obrigatórios (TR 9.19); curso primeiros socorros; toxicológico CNH D.
A27: Preposto / supervisor local + apoio administrativo | B27: 7500 | C27: R$/mês (total) | D27: Preposto formal obrigatório (TR 9.4). Relatórios mensais de telemetria + presença (TR 10.5). Salário + encargos.
A29: 4. VEÍCULO — van ≥15 lugares, ≤5 anos e ≤150.000 km (TR 8.8/8.10) — custo fixo mensal por van
A30: Valor da van (ex.: Sprinter 415/517, Master, Ducato — 2–3 anos) | B30: 290000 | C30: R$ | D30: ESTIMATIVA FIPE set/2026. Vans com >5 anos ou >150 mil km ficam INELEGÍVEIS durante o contrato → renovação obrigatória.
A31: Depreciação anual | B31: 0.15 | C31: % a.a. | D31: Van roda ~90–100 mil km/ano no Item 01 → atinge 150 mil km em ~18 meses se comprada usada. Considere veículo 0 km ou troca.
A32: Custo de capital / financiamento (CDC/consórcio) | B32: 0.15 | C32: % a.a. | D32: Taxa média dos contratos de financiamento da Azul.
A33: Seguro casco + RCF-V (DM 40 mil / DC 100 mil / DMo 5 mil — TR 9.17) | B33: 750 | C33: R$/mês | D33: ESTIMATIVA. Apólice exigida antes do início.
A34: IPVA + licenciamento + DPVAT (PR) | B34: 3800 | C34: R$/ano | D34: PR: micro-ônibus/transporte coletivo tem alíquota reduzida; conferir enquadramento da van.
A35: Telemetria HÍBRIDA (GPRS + satélite) + plataforma web | B35: 260 | C35: R$/mês por van | D35: Rastreamento GPRS no dia 1 e satélite/híbrido em 60 dias (TR 2.21–2.23, 9.24–9.26). Ituran/Onixsat/Sascar híbrido custa 2–3× o GPRS comum.
A36: Sistema de controle de embarque (QR Code/biometria/app) + relatório de frequência | B36: 90 | C36: R$/mês por van | D36: Obrigatório e condição de pagamento (TR 9.27–9.31). App + tablet/celular embarcado.
A37: Higienização diária + desinfecção periódica | B37: 320 | C37: R$/mês por van | D37: TR 9.21. Produtos + mão de obra.
A38: Acessibilidade (barras, estribo/escada móvel) + identificação visual (adesivagem) | B38: 45 | C38: R$/mês por van | D38: R$ ~2.700 por van amortizado em 5 anos (TR 8.12, 9.20).
A39: Laudo técnico anual de frota + vistorias | B39: 600 | C39: R$/ano por van | D39: Relatório assinado por profissional em 5 dias úteis (TR 5.7); CRLV anual (TR 8.11).
A40: Garagem / base operacional em São José dos Pinhais (rateio) | B40: 700 | C40: R$/mês por van | D40: ESTIMATIVA: pátio + sala ~R$ 6.000/mês ÷ 8–9 vans. Sede da Azul é em SP → base local obrigatória; pátio público vedado (TR 8.27).
A42: 5. INSUMOS VARIÁVEIS (por km rodado)
A43: Diesel S10 — preço bomba (Curitiba/RMC) | B43: 6.05 | C43: R$/litro | D43: ESTIMATIVA ANP PR set/2026. Reajuste só após 12 meses do orçamento (22/06/2026) pelo IPCA — variação de diesel entre 06/2026 e 06/2027 é risco da contratada.
A44: Consumo médio da van (urbano/rodoviário misto, ar-condicionado) | B44: 8.5 | C44: km/litro | D44: Sprinter/Master diesel com carga de passageiros: 8–9,5 km/l.
A45: ARLA 32 (uso obrigatório, notas arquivadas — TR 5.2) | B45: 0.04 | C45: R$/km | D45: ~4% do diesel × R$ 4/l.
...

Sheet Rotas
A1: ROTAS E QUANTITATIVOS — TR 225/2026 item 12.5 e Anexo II (itinerários)
A2: Km/mês máximo registrado por rota (edital). Vans e motoristas dimensionados a partir do km/dia e da jornada. Preço máximo R$ 11,11/km nos dois itens (Anexo III).
A4: Item | B4: Rota | C4: Km/mês máx. (edital) | D4: Km/ano máx. | E4: Dias/mês | F4: Km/dia | G4: Vans operacionais | H4: Motoristas | I4: Viagens/dia (est.) | J4: Passagens pedágio/mês | K4: Pedágio R$/mês | L4: Preço máx. (R$/km) | M4: Valor máx. anual (R$)
A5: 1 | B5: Hemodiálise — ROTA NORTE | C5: 7800 | D5: =C5*12 -> 93600 | E5: =Premissas!$B$13 -> 26 | F5: =IF(E5=0,0,C5/E5) -> 300 | G5: 1 | H5: =G5*Premissas!$B$21 -> 1.8 | I5: 6 | J5: =I5*E5*Premissas!$B$54*Premissas!$B$55 -> 31.2 | K5: =J5*Premissas!$B$51 -> 374.4 | L5: 11.11 | M5: =D5*L5 -> 1039896
A6: 1 | B6: Hemodiálise — ROTA SUL | C6: 7800 | D6: =C6*12 -> 93600 | E6: =Premissas!$B$13 -> 26 | F6: =IF(E6=0,0,C6/E6) -> 300 | G6: 1 | H6: =G6*Premissas!$B$21 -> 1.8 | I6: 6 | J6: =I6*E6*Premissas!$B$54*Premissas!$B$55 -> 31.2 | K6: =J6*Premissas!$B$51 -> 374.4 | L6: 11.11 | M6: =D6*L6 -> 1039896
A7: 1 | B7: Hemodiálise — ROTA CENTRO | C7: 7800 | D7: =C7*12 -> 93600 | E7: =Premissas!$B$13 -> 26 | F7: =IF(E7=0,0,C7/E7) -> 300 | G7: 1 | H7: =G7*Premissas!$B$21 -> 1.8 | I7: 6 | J7: =I7*E7*Premissas!$B$54*Premissas!$B$55 -> 31.2 | K7: =J7*Premissas!$B$51 -> 374.4 | L7: 11.11 | M7: =D7*L7 -> 1039896
A8: 1 | B8: Hemodiálise — ROTA SUDESTE | C8: 7800 | D8: =C8*12 -> 93600 | E8: =Premissas!$B$13 -> 26 | F8: =IF(E8=0,0,C8/E8) -> 300 | G8: 1 | H8: =G8*Premissas!$B$21 -> 1.8 | I8: 6 | J8: =I8*E8*Premissas!$B$54*Premissas!$B$55 -> 31.2 | K8: =J8*Premissas!$B$51 -> 374.4 | L8: 11.11 | M8: =D8*L8 -> 1039896
A9: 2 | B9: Servidores — ROTA 01 (UBS Campina do Taquaral, Cachoeira, Agaraú, Cotia, Marcelino) | C9: 1800 | D9: =C9*12 -> 21600 | E9: =Premissas!$B$14 -> 22 | F9: =IF(E9=0,0,C9/E9) -> 81.818182 | G9: 1 | H9: =G9*Premissas!$B$22 -> 1 | I9: 1 | J9: =E9*2 -> 44 | K9: =J9*Premissas!$B$53 -> 0 | L9: 11.11 | M9: =D9*L9 -> 239976
A10: 2 | B10: Servidores — ROTA 02 (UBS Malhada, Córrego Fundo) | C10: 2000 | D10: =C10*12 -> 24000 | E10: =Premissas!$B$14 -> 22 | F10: =IF(E10=0,0,C10/E10) -> 90.909091 | G10: 1 | H10: =G10*Premissas!$B$22 -> 1 | I10: 1 | J10: =E10*2 -> 44 | K10: =J10*Premissas!$B$53 -> 0 | L10: 11.11 | M10: =D10*L10 -> 266640
A11: 2 | B11: Servidores — ROTA 03 (UBS Faxina, Contenda, Campo Largo da Roseira) | C11: 1800 | D11: =C11*12 -> 21600 | E11: =Premissas!$B$14 -> 22 | F11: =IF(E11=0,0,C11/E11) -> 81.818182 | G11: 1 | H11: =G11*Premissas!$B$22 -> 1 | I11: 1 | J11: =E11*2 -> 44 | K11: =J11*Premissas!$B$53 -> 0 | L11: 11.11 | M11: =D11*L11 -> 239976
B12: Subtotal Item 01 — pacientes | C12: =SUMIF($A$5:$A$11,1,C5:C11) -> 31200 | D12: =SUMIF($A$5:$A$11,1,D5:D11) -> 374400 | G12: =SUMIF($A$5:$A$11,1,G5:G11) -> 4 | H12: =SUMIF($A$5:$A$11,1,H5:H11) -> 7.2 | J12: =SUMIF($A$5:$A$11,1,J5:J11) -> 124.8 | K12: =SUMIF($A$5:$A$11,1,K5:K11) -> 1497.6 | M12: =SUMIF($A$5:$A$11,1,M5:M11) -> 4159584
B13: Subtotal Item 02 — servidores | C13: =SUMIF($A$5:$A$11,2,C5:C11) -> 5600 | D13: =SUMIF($A$5:$A$11,2,D5:D11) -> 67200 | G13: =SUMIF($A$5:$A$11,2,G5:G11) -> 3 | H13: =SUMIF($A$5:$A$11,2,H5:H11) -> 3 | J13: =SUMIF($A$5:$A$11,2,J5:J11) -> 132 | K13: =SUMIF($A$5:$A$11,2,K5:K11) -> 0 | M13: =SUMIF($A$5:$A$11,2,M5:M11) -> 746592
B14: TOTAL LOTE | C14: =C12+C13 -> 36800 | D14: =D12+D13 -> 441600 | G14: =G12+G13 -> 7 | H14: =H12+H13 -> 10.2 | J14: =J12+J13 -> 256.8 | K14: =K12+K13 -> 1497.6 | M14: =M12+M13 -> 4906176
A16: Frota com reserva técnica (vans): | G16: =ROUNDUP(G14*(1+Premissas!$B$17),0) -> 9
A17: Leitura do edital: hemodiálise ≈ 1.200 km/dia no total (Anexo II) = 300 km/van/dia em 3 turnos (06h–19h). Servidores: 80/100/80 km/dia, saída 07h, retorno 17h. Vans ≥15 lugares, ≤5 anos, ≤150.000 km; mínimo 6 vans na frota inicial; substituição em 2 h.

Sheet Composição de Custo
A1: COMPOSIÇÃO DE CUSTO POR ITEM (mensal, na utilização esperada) → CUSTO/KM → PREÇO/KM
A2: Custos fixos independem do km faturado; por isso o custo/km sobe quando a utilização cai (ver Cenários). Preço = custo ÷ (1 − lucro − tributos − custo financeiro).
A4: Componente | B4: Item 01 — Pacientes (R$/mês) | C4: Item 02 — Servidores (R$/mês) | D4: Lote (R$/mês) | E4: Memória de cálculo
A5: A. KM
A6: Km útil faturável no mês (máx. edital × utilização) | B6: =Rotas!C12*Premissas!$B$15 -> 26520 | C6: =Rotas!C13*Premissas!$B$15 -> 4760 | D6: =B6+C6 -> 31280 | E6: Rotas × Premissas.utilização
A7: Km rodado total (útil + km improdutivo) | B7: =B6*(1+Premissas!$B$16) -> 30498 | C7: =C6*(1+Premissas!$B$16) -> 5474 | D7: =B7+C7 -> 35972 | E7: × (1 + km morto)
A8: Vans operacionais / com reserva | B8: =Rotas!G12 -> 4 | C8: =Rotas!G13 -> 3 | D8: =B8+C8 -> 7 | E8: Rotas (reserva rateada no custo do veículo)
A9: Motoristas | B9: =Rotas!H12 -> 7.2 | C9: =Rotas!H13 -> 3 | D9: =B9+C9 -> 10.2 | E9: Rotas
A10: B. MÃO DE OBRA (fixo)
A11: Salários motoristas c/ horas extras | B11: =B9*Premissas!$B$20*(1+Premissas!$B$23) -> 23788.8 | C11: =C9*Premissas!$B$20*(1+Premissas!$B$23) -> 9912 | D11: =B11+C11 -> 33700.8 | E11: motoristas × salário × (1+HE)
A12: Encargos e provisões | B12: =B11*Premissas!$B$24 -> 16652.16 | C12: =C11*Premissas!$B$24 -> 6938.4 | D12: =B12+C12 -> 23590.56 | E12: × encargos
A13: Benefícios + uniforme/EPI/cursos | B13: =B9*(Premissas!$B$25+Premissas!$B$26) -> 7488 | C13: =C9*(Premissas!$B$25+Premissas!$B$26) -> 3120 | D13: =B13+C13 -> 10608 | E13: motoristas × (benefícios + EPI)
A14: Preposto / supervisão local (rateio por km) | B14: =Premissas!$B$27*B6/(B6+C6) -> 6358.6957 | C14: =Premissas!$B$27*C6/(B6+C6) -> 1141.3043 | D14: =B14+C14 -> 7500 | E14: rateado proporcional ao km
A15: Subtotal mão de obra | B15: =SUM(B11:B14) -> 54287.656 | C15: =SUM(C11:C14) -> 21111.704 | D15: =B15+C15 -> 75399.36
A16: C. VEÍCULOS (fixo, por van, com reserva técnica)
A17: Depreciação + custo de capital | B17: =B8*(1+Premissas!$B$17)*Premissas!$B$30*(Premissas!$B$31+Premissas!$B$32)/12 -> 33350 | C17: =C8*(1+Premissas!$B$17)*Premissas!$B$30*(Premissas!$B$31+Premissas!$B$32)/12 -> 25012.5 | D17: =B17+C17 -> 58362.5 | E17: vans × (1+reserva) × valor × (deprec.+capital) ÷ 12
A18: Seguro casco + RCF-V | B18: =B8*(1+Premissas!$B$17)*Premissas!$B$33 -> 3450 | C18: =C8*(1+Premissas!$B$17)*Premissas!$B$33 -> 2587.5 | D18: =B18+C18 -> 6037.5
A19: IPVA / licenciamento + laudo anual | B19: =B8*(1+Premissas!$B$17)*(Premissas!$B$34+Premissas!$B$39)/12 -> 1686.6667 | C19: =C8*(1+Premissas!$B$17)*(Premissas!$B$34+Premissas!$B$39)/12 -> 1265 | D19: =B19+C19 -> 2951.6667
A20: Telemetria híbrida + sistema de embarque | B20: =B8*(1+Premissas!$B$17)*(Premissas!$B$35+Premissas!$B$36) -> 1610 | C20: =C8*(1+Premissas!$B$17)*(Premissas!$B$35+Premissas!$B$36) -> 1207.5 | D20: =B20+C20 -> 2817.5 | E20: exigência TR 2.21–2.23 / 9.27
A21: Higienização + acessibilidade/identificação | B21: =B8*(Premissas!$B$37+Premissas!$B$38) -> 1460 | C21: =C8*(Premissas!$B$37+Premissas!$B$38) -> 1095 | D21: =B21+C21 -> 2555
A22: Garagem / base local | B22: =B8*(1+Premissas!$B$17)*Premissas!$B$40 -> 3220 | C22: =C8*(1+Premissas!$B$17)*Premissas!$B$40 -> 2415 | D22: =B22+C22 -> 5635
A23: Subtotal veículos | B23: =SUM(B17:B22) -> 44776.667 | C23: =SUM(C17:C22) -> 33582.5 | D23: =B23+C23 -> 78359.167
A24: D. INSUMOS VARIÁVEIS (por km rodado)
A25: Diesel | B25: =B7/Premissas!$B$44*Premissas!$B$43 -> 21707.4 | C25: =C7/Premissas!$B$44*Premissas!$B$43 -> 3896.2 | D25: =B25+C25 -> 25603.6 | E25: km rodado ÷ km/l × R$/l
A26: ARLA 32 | B26: =B7*Premissas!$B$45 -> 1219.92 | C26: =C7*Premissas!$B$45 -> 218.96 | D26: =B26+C26 -> 1438.88
A27: Pneus | B27: =B7*Premissas!$B$46 -> 3964.74 | C27: =C7*Premissas!$B$46 -> 711.62 | D27: =B27+C27 -> 4676.36
A28: Manutenção | B28: =B7*Premissas!$B$47 -> 14639.04 | C28: =C7*Premissas!$B$47 -> 2627.52 | D28: =B28+C28 -> 17266.56
A29: Lavagem / lubrificantes | B29: =B7*Premissas!$B$48 -> 1524.9 | C29: =C7*Premissas!$B$48 -> 273.7 | D29: =B29+C29 -> 1798.6
A30: Pedágio | B30: =Rotas!K12 -> 1497.6 | C30: =Rotas!K13 -> 0 | D30: =B30+C30 -> 1497.6 | E30: aba Rotas × tarifas
A31: Subtotal variáveis | B31: =SUM(B25:B30) -> 44553.6 | C31: =SUM(C25:C30) -> 7728 | D31: =B31+C31 -> 52281.6
A32: E. TOTAIS
A33: Custo direto | B33: =B15+B23+B31 -> 143617.92 | C33: =C15+C23+C31 -> 62422.204 | D33: =B33+C33 -> 206040.13 | E33: B + C + D
A34: Administração central + contingência | B34: =B33*(Premissas!$B$58+Premissas!$B$59) -> 14361.792 | C34: =C33*(Premissas!$B$58+Premissas!$B$59) -> 6242.2204 | D34: =B34+C34 -> 20604.013 | E34: × (adm + risco)
A35: CUSTO TOTAL / MÊS | B35: =B33+B34 -> 157979.71 | C35: =C33+C34 -> 68664.425 | D35: =B35+C35 -> 226644.14
A36: Custo por km útil (R$/km) | B36: =IF(B6=0,0,B35/B6) -> 5.9570028 | C36: =IF(C6=0,0,C35/C6) -> 14.425299 | D36: =IF((B6+C6)=0,0,D35/(B6+C6)) -> 7.2456566 | E36: custo ÷ km faturável
A37: do qual: custo fixo por km | B37: =IF(B6=0,0,(B15+B23)/B6) -> 3.7354571 | C37: =IF(C6=0,0,(C15+C23)/C6) -> 11.490379
A38: do qual: custo variável por km | B38: =IF(B6=0,0,(B31+B34)/B6) -> 2.2215457 | C38: =IF(C6=0,0,(C31+C34)/C6) -> 2.9349203
A39: F. PREÇO
A40: Tributos sobre faturamento (média do item) | B40: =Premissas!$B$70 -> 0.1223 | C40: =Premissas!$B$71 -> 0.0908 | D40: =IF((B47+C47)=0,0,(B40*B47+C40*C47)/(B47+C47)) -> 0.11301997 | E40: Premissas (ISS municipal / ICMS intermunicipal)
A41: Custo financeiro (prazo de pagamento) | B41: =Premissas!$B$74 -> 0.018 | C41: =Premissas!$B$74 -> 0.018 | D41: =IF((B47+C47)=0,0,(B41*B47+C41*C47)/(B47+C47)) -> 0.018 | E41: Premissas
...

Sheet Cenários
A1: CENÁRIOS — sensibilidade do preço/km à utilização do km registrado e lucro obtido em cada lance
A2: Como o SRP só paga km útil e as rotas externas entram na Fase 2, o custo fixo pode ficar diluído em menos km. A tabela mostra o preço/km necessário (lucro alvo) e o lucro real ao preço escolhido, por utilização. Fórmulas usam os custos fixos e variáveis da aba Composição.
A4: Preço/km a lançar (teste) | B4: 9.9 | C4: ← edite para simular seu lance (lote único: mesmo preço nos 2 itens, teto R$ 11,11; lances de R$ 0,20)
A6: Utilização do km máximo | B6: 0.6 | C6: 0.7 | D6: 0.8 | E6: 0.85 | F6: 0.9 | G6: 1
A7: Km útil faturável / mês | B7: =(Rotas!C14)*B6 -> 22080 | C7: =(Rotas!C14)*C6 -> 25760 | D7: =(Rotas!C14)*D6 -> 29440 | E7: =(Rotas!C14)*E6 -> 31280 | F7: =(Rotas!C14)*F6 -> 33120 | G7: =(Rotas!C14)*G6 -> 36800
A8: Custo total / mês (R$) | B8: =((('Composição de Custo'!D15+'Composição de Custo'!D23))+(('Composição de Custo'!D31-'Composição de Custo'!D30)/'Composição de Custo'!D7)*B7*(1+Premissas!$B$16)+('Composição de Custo'!D30)*B6)*(1+(Premissas!$B$58+Premissas!$B$59)) -> 209555.08 | C8: =((('Composição de Custo'!D15+'Composição de Custo'!D23))+(('Composição de Custo'!D31-'Composição de Custo'!D30)/'Composição de Custo'!D7)*C7*(1+Premissas!$B$16)+('Composição de Custo'!D30)*C6)*(1+(Premissas!$B$58+Premissas!$B$59)) -> 216291.86 | D8: =((('Composição de Custo'!D15+'Composição de Custo'!D23))+(('Composição de Custo'!D31-'Composição de Custo'!D30)/'Composição de Custo'!D7)*D7*(1+Premissas!$B$16)+('Composição de Custo'!D30)*D6)*(1+(Premissas!$B$58+Premissas!$B$59)) -> 223028.64 | E8: =((('Composição de Custo'!D15+'Composição de Custo'!D23))+(('Composição de Custo'!D31-'Composição de Custo'!D30)/'Composição de Custo'!D7)*E7*(1+Premissas!$B$16)+('Composição de Custo'!D30)*E6)*(1+(Premissas!$B$58+Premissas!$B$59)) -> 226397.04 | F8: =((('Composição de Custo'!D15+'Composição de Custo'!D23))+(('Composição de Custo'!D31-'Composição de Custo'!D30)/'Composição de Custo'!D7)*F7*(1+Premissas!$B$16)+('Composição de Custo'!D30)*F6)*(1+(Premissas!$B$58+Premissas!$B$59)) -> 229765.43 | G8: =((('Composição de Custo'!D15+'Composição de Custo'!D23))+(('Composição de Custo'!D31-'Composição de Custo'!D30)/'Composição de Custo'!D7)*G7*(1+Premissas!$B$16)+('Composição de Custo'!D30)*G6)*(1+(Premissas!$B$58+Premissas!$B$59)) -> 236502.21
A9: Custo por km útil (R$/km) | B9: =IF(B7=0,0,B8/B7) -> 9.4907191 | C9: =IF(C7=0,0,C8/C7) -> 8.3964232 | D9: =IF(D7=0,0,D8/D7) -> 7.5757012 | E9: =IF(E7=0,0,E8/E7) -> 7.2377569 | F9: =IF(F7=0,0,F8/F7) -> 6.9373619 | G9: =IF(G7=0,0,G8/G7) -> 6.4266905
A10: Preço/km p/ lucro alvo (R$/km) | B10: =ROUNDUP(B9/(1-(Premissas!$B$60)-('Composição de Custo'!D40)-(Premissas!$B$74)),2) -> 12.19 | C10: =ROUNDUP(C9/(1-(Premissas!$B$60)-('Composição de Custo'!D40)-(Premissas!$B$74)),2) -> 10.78 | D10: =ROUNDUP(D9/(1-(Premissas!$B$60)-('Composição de Custo'!D40)-(Premissas!$B$74)),2) -> 9.73 | E10: =ROUNDUP(E9/(1-(Premissas!$B$60)-('Composição de Custo'!D40)-(Premissas!$B$74)),2) -> 9.3 | F10: =ROUNDUP(F9/(1-(Premissas!$B$60)-('Composição de Custo'!D40)-(Premissas!$B$74)),2) -> 8.91 | G10: =ROUNDUP(G9/(1-(Premissas!$B$60)-('Composição de Custo'!D40)-(Premissas!$B$74)),2) -> 8.26
A11: Preço/km lucro zero (R$/km) | B11: =B9/(1-('Composição de Custo'!D40)-(Premissas!$B$74)) -> 10.921677 | C11: =C9/(1-('Composição de Custo'!D40)-(Premissas!$B$74)) -> 9.662389 | D11: =D9/(1-('Composição de Custo'!D40)-(Premissas!$B$74)) -> 8.7179232 | E11: =E9/(1-('Composição de Custo'!D40)-(Premissas!$B$74)) -> 8.3290255 | F11: =F9/(1-('Composição de Custo'!D40)-(Premissas!$B$74)) -> 7.9833387 | G11: =G9/(1-('Composição de Custo'!D40)-(Premissas!$B$74)) -> 7.3956711
A12: — Ao preço de teste (B4) —
A13: Faturamento / mês (R$) | B13: =$B$4*B7 -> 218592 | C13: =$B$4*C7 -> 255024 | D13: =$B$4*D7 -> 291456 | E13: =$B$4*E7 -> 309672 | F13: =$B$4*F7 -> 327888 | G13: =$B$4*G7 -> 364320
A14: Lucro líquido / mês (R$) | B14: =B13*(1-('Composição de Custo'!D40)-(Premissas!$B$74))-B8 -> -19602.994 | C14: =C13*(1-('Composição de Custo'!D40)-(Premissas!$B$74))-C8 -> 5318.9035 | D14: =D13*(1-('Composição de Custo'!D40)-(Premissas!$B$74))-D8 -> 30240.801 | E14: =E13*(1-('Composição de Custo'!D40)-(Premissas!$B$74))-E8 -> 42701.75 | F14: =F13*(1-('Composição de Custo'!D40)-(Premissas!$B$74))-F8 -> 55162.699 | G14: =G13*(1-('Composição de Custo'!D40)-(Premissas!$B$74))-G8 -> 80084.596
A15: Margem líquida | B15: =IF(B13=0,0,B14/B13) -> -0.089678461 | C15: =IF(C13=0,0,C14/C13) -> 0.020856482 | D15: =IF(D13=0,0,D14/D13) -> 0.10375769 | E15: =IF(E13=0,0,E14/E13) -> 0.13789348 | F15: =IF(F13=0,0,F14/F13) -> 0.16823641 | G15: =IF(G13=0,0,G14/G13) -> 0.21981938
A16: Lucro líquido / ano (R$) | B16: =B14*Premissas!$B$12 -> -235235.93 | C16: =C14*Premissas!$B$12 -> 63826.842 | D16: =D14*Premissas!$B$12 -> 362889.61 | E16: =E14*Premissas!$B$12 -> 512421 | F16: =F14*Premissas!$B$12 -> 661952.38 | G16: =G14*Premissas!$B$12 -> 961015.15
A17: Lucro / van / mês (R$) | B17: =IF(Rotas!G14=0,0,B14/Rotas!G14) -> -2800.4277 | C17: =IF(Rotas!G14=0,0,C14/Rotas!G14) -> 759.84335 | D17: =IF(Rotas!G14=0,0,D14/Rotas!G14) -> 4320.1144 | E17: =IF(Rotas!G14=0,0,E14/Rotas!G14) -> 6100.25 | F17: =IF(Rotas!G14=0,0,F14/Rotas!G14) -> 7880.3855 | G17: =IF(Rotas!G14=0,0,G14/Rotas!G14) -> 11440.657
A19: Leitura: a coluna 100% é o cenário do edital; 60–70% representa a Fase 1 (só CDR local + UBS, sem rotas externas). Se o lucro/mês ficar negativo na coluna de 60–70%, o lance está exposto ao risco de ociosidade que o TR 10.3 aloca à contratada.

Sheet Proposta
A1: PROPOSTA DE PREÇOS — PREGÃO ELETRÔNICO Nº 089/2026-SERMALI — Prefeitura Municipal de São José dos Pinhais/PR — LOTE 01
A3: Licitante: | B3: =Premissas!$B$6&" — CNPJ "&Premissas!$B$7 -> AZUL TRANSPORTES E TURISMO LTDA — CNPJ 10.764.533/0001-01
A4: Endereço: | B4: =Premissas!$B$8 -> 0
A5: Representante: | B5: =Premissas!$B$9 -> 0
A7: Item | B7: Descrição do serviço | C7: Quant. km/ano | D7: Preço máx. (R$/km) | E7: Preço proposto (R$/km) | F7: Valor total (R$)
A8: 1 | B8: SERVIÇO DE TRANSPORTE DE PACIENTES – DIÁLISE (rotas Norte, Sul, Centro e Sudeste — 7.800 km/mês cada) | C8: =Rotas!D12 -> 374400 | D8: 11.11 | E8: =ROUNDUP('Composição de Custo'!D43,2) -> 9.31 | F8: =C8*E8 -> 3485664
A9: 2 | B9: SERVIÇO DE TRANSPORTE C/ VAN – SERVIDORES (rotas 01, 02 e 03 — UBS rurais) | C9: =Rotas!D13 -> 67200 | D9: 11.11 | E9: =ROUNDUP('Composição de Custo'!D43,2) -> 9.31 | F9: =C9*E9 -> 625632
B10: VALOR TOTAL DO LOTE 01 (12 meses) | F10: =F8+F9 -> 4111296
B11: Valor máximo do edital | F11: =C8*D8+C9*D9 -> 4906176
B12: Desconto sobre o valor máximo | F12: =IF(F11=0,0,1-F10/F11) -> 0.1620162
A14: Nota: em lote único com disputa aberta, o lance é dado sobre o valor unitário; o preço proposto aqui é o preço médio ponderado do lote (mesmo valor nos dois itens), pois o Item 02 isolado custa mais que o teto de R$ 11,11 e só fecha subsidiado pelo Item 01 e confira o lucro na aba Cenários. Os preços incluem todos os custos diretos e indiretos, tributos, pedágios, telemetria, seguros e lucro. Validade: conforme edital. Pagamento: 30 dias. Reajuste: IPCA após 12 meses de 22/06/2026.
